<?xml version="1.0" encoding="utf-8"?>
<!-- This URDF was automatically created by SolidWorks to URDF Exporter! Originally created by Stephen Brawner (brawner@gmail.com) 
     Commit Version: 1.5.1-0-g916b5db  Build Version: 1.5.7152.31018
     For more information, please see http://wiki.ros.org/sw_urdf_exporter -->
<robot
  name="lbr_iiwa7_r800">
  <link
    name="iiwa7_link_0">
    <inertial>
      <origin
        xyz="-0.012856764088336 7.05371084939836E-07 0.0679655592591469"
        rpy="0 0 0" />
      <mass
        value="30.2763517543289" />
      <inertia
        ixx="0.111239565538359"
        ixy="-3.81097437253422E-07"
        ixz="0.00486659750522703"
        iyy="0.139017104291389"
        iyz="7.87871531503135E-07"
        izz="0.133028621926226" />
    </inertial>
    <visual>
      <origin
        xyz="0 0 0"
        rpy="0 0 0" />
      <geometry>
        <mesh
          filename="./meshes/base_link.STL" />
      </geometry>
      <material
        name="">
        <color
          rgba="0.647058823529412 0.619607843137255 0.588235294117647 1" />
      </material>
    </visual>
    <collision>
      <origin
        xyz="0 0 0"
        rpy="0 0 0" />
      <geometry>
        <mesh
          filename="./meshes/base_link.STL" />
      </geometry>
    </collision>
  </link>
  <link
    name="iiwa7_link_1">
    <inertial>
      <origin
        xyz="-4.78790441849064E-07 -0.0348192058752328 -0.0692021315991948"
        rpy="0 0 0" />
      <mass
        value="21.1627406257303" />
      <inertia
        ixx="0.133321610552378"
        ixy="-5.3830316300325E-07"
        ixz="9.16989471201082E-07"
        iyy="0.127213841326705"
        iyz="0.0236704924620788"
        izz="0.047155320135412" />
    </inertial>
    <visual>
      <origin
        xyz="0 0 0"
        rpy="0 0 0" />
      <geometry>
        <mesh
          filename="./meshes/iiwa7_link_1.STL" />
      </geometry>
      <material
        name="">
        <color
          rgba="0.647058823529412 0.619607843137255 0.588235294117647 1" />
      </material>
    </visual>
    <collision>
      <origin
        xyz="0 0 0"
        rpy="0 0 0" />
      <geometry>
        <mesh
          filename="./meshes/iiwa7_link_1.STL" />
      </geometry>
    </collision>
  </link>
  <joint
    name="iiwa7_joint_1"
    type="revolute">
    <origin
      xyz="0 0 0.3375"
      rpy="0 0 0" />
    <parent
      link="iiwa7_link_0" />
    <child
      link="iiwa7_link_1" />
    <axis
      xyz="0 0 -1" />
    <limit
      lower="-2.97"
      upper="2.97"
      effort="176"
      velocity="1.71" />
  </joint>
  <link
    name="iiwa7_link_2">
    <inertial>
      <origin
        xyz="-5.2906167189587E-07 -0.0869460684741495 0.0287906957294968"
        rpy="0 0 0" />
      <mass
        value="25.1403147192251" />
      <inertia
        ixx="0.197631241693207"
        ixy="9.50708464039702E-08"
        ixz="-3.51963818841194E-07"
        iyy="0.0602720613821397"
        iyz="-0.0367196702125505"
        izz="0.187557269753206" />
    </inertial>
    <visual>
      <origin
        xyz="0 0 0"
        rpy="0 0 0" />
      <geometry>
        <mesh
          filename="./meshes/iiwa7_link_2.STL" />
      </geometry>
      <material
        name="">
        <color
          rgba="0.647058823529412 0.619607843137255 0.588235294117647 1" />
      </material>
    </visual>
    <collision>
      <origin
        xyz="0 0 0"
        rpy="0 0 0" />
      <geometry>
        <mesh
          filename="./meshes/iiwa7_link_2.STL" />
      </geometry>
    </collision>
  </link>
  <joint
    name="iiwa7_joint_2"
    type="revolute">
    <origin
      xyz="0 0 0"
      rpy="-1.5708 0 0" />
    <parent
      link="iiwa7_link_1" />
    <child
      link="iiwa7_link_2" />
    <axis
      xyz="0 0 1" />
    <limit
      lower="-2.09"
      upper="2.09"
      effort="176"
      velocity="1.71" />
  </joint>
  <link
    name="iiwa7_link_3">
    <inertial>
      <origin
        xyz="8.94264666317923E-07 0.0343188244798595 -0.0692020521907963"
        rpy="0 0 0" />
      <mass
        value="21.1627874292289" />
      <inertia
        ixx="0.133322417523041"
        ixy="-2.72387851582384E-07"
        ixz="-2.31579646685682E-07"
        iyy="0.127213838333813"
        iyz="-0.0236710393468367"
        izz="0.0471557500559207" />
    </inertial>
    <visual>
      <origin
        xyz="0 0 0"
        rpy="0 0 0" />
      <geometry>
        <mesh
          filename="./meshes/iiwa7_link_3.STL" />
      </geometry>
      <material
        name="">
        <color
          rgba="0.647058823529412 0.619607843137255 0.588235294117647 1" />
      </material>
    </visual>
    <collision>
      <origin
        xyz="0 0 0"
        rpy="0 0 0" />
      <geometry>
        <mesh
          filename="./meshes/iiwa7_link_3.STL" />
      </geometry>
    </collision>
  </link>
  <joint
    name="iiwa7_joint_3"
    type="revolute">
    <origin
      xyz="0 -0.3993 0"
      rpy="1.5708 0 0" />
    <parent
      link="iiwa7_link_2" />
    <child
      link="iiwa7_link_3" />
    <axis
      xyz="0 0 -1" />
    <limit
      lower="-2.97"
      upper="2.97"
      effort="110"
      velocity="1.75" />
  </joint>
  <link
    name="iiwa7_link_4">
    <inertial>
      <origin
        xyz="9.9343785475714E-08 -0.0869462342636022 -0.0292907044657978"
        rpy="0 0 0" />
      <mass
        value="25.140328983289" />
      <inertia
        ixx="0.197630839812683"
        ixy="-3.9082887807781E-07"
        ixz="-3.24564289064112E-07"
        iyy="0.0602723071447973"
        iyz="0.0367195588674331"
        izz="0.187556898167347" />
    </inertial>
    <visual>
      <origin
        xyz="0 0 0"
        rpy="0 0 0" />
      <geometry>
        <mesh
          filename="./meshes/iiwa7_link_4.STL" />
      </geometry>
      <material
        name="">
        <color
          rgba="0.647058823529412 0.619607843137255 0.588235294117647 1" />
      </material>
    </visual>
    <collision>
      <origin
        xyz="0 0 0"
        rpy="0 0 0" />
      <geometry>
        <mesh
          filename="./meshes/iiwa7_link_4.STL" />
      </geometry>
    </collision>
  </link>
  <joint
    name="iiwa7_joint_4"
    type="revolute">
    <origin
      xyz="0 0 0"
      rpy="-1.5708 0 0" />
    <parent
      link="iiwa7_link_3" />
    <child
      link="iiwa7_link_4" />
    <axis
      xyz="0 0 -1" />
    <limit
      lower="-2.09"
      upper="2.09"
      effort="110"
      velocity="2.27" />
  </joint>
  <link
    name="iiwa7_link_5">
    <inertial>
      <origin
        xyz="-1.5059645121912E-07 -0.0298223596156005 -0.116233672352317"
        rpy="0 0 0" />
      <mass
        value="9.53466992761605" />
      <inertia
        ixx="0.0529038960536523"
        ixy="6.86274869084724E-08"
        ixz="3.57472026918582E-07"
        iyy="0.0444942713885967"
        iyz="0.0174914068345989"
        izz="0.0239916848880951" />
    </inertial>
    <visual>
      <origin
        xyz="0 0 0"
        rpy="0 0 0" />
      <geometry>
        <mesh
          filename="./meshes/iiwa7_link_5.STL" />
      </geometry>
      <material
        name="">
        <color
          rgba="0.647058823529412 0.619607843137255 0.588235294117647 1" />
      </material>
    </visual>
    <collision>
      <origin
        xyz="0 0 0"
        rpy="0 0 0" />
      <geometry>
        <mesh
          filename="./meshes/iiwa7_link_5.STL" />
      </geometry>
    </collision>
  </link>
  <joint
    name="iiwa7_joint_5"
    type="revolute">
    <origin
      xyz="0 -0.3993 0"
      rpy="1.5708 0 0" />
    <parent
      link="iiwa7_link_4" />
    <child
      link="iiwa7_link_5" />
    <axis
      xyz="0 0 -1" />
    <limit
      lower="-2.97"
      upper="2.97"
      effort="110"
      velocity="2.44" />
  </joint>
  <link
    name="iiwa7_link_6">
    <inertial>
      <origin
        xyz="3.09820422451923E-06 -0.000588422963829549 0.000348569863276505"
        rpy="0 0 0" />
      <mass
        value="14.2007599322815" />
      <inertia
        ixx="0.0384515762635731"
        ixy="-6.70279497724119E-08"
        ixz="2.19173188415509E-06"
        iyy="0.0280010940276735"
        iyz="-0.00192249677468735"
        izz="0.0368124806983828" />
    </inertial>
    <visual>
      <origin
        xyz="0 0 0"
        rpy="0 0 0" />
      <geometry>
        <mesh
          filename="./meshes/iiwa7_link_6.STL" />
      </geometry>
      <material
        name="">
        <color
          rgba="0.647058823529412 0.619607843137255 0.588235294117647 1" />
      </material>
    </visual>
    <collision>
      <origin
        xyz="0 0 0"
        rpy="0 0 0" />
      <geometry>
        <mesh
          filename="./meshes/iiwa7_link_6.STL" />
      </geometry>
    </collision>
  </link>
  <joint
    name="iiwa7_joint_6"
    type="revolute">
    <origin
      xyz="0 0 0"
      rpy="-1.5708 0 0" />
    <parent
      link="iiwa7_link_5" />
    <child
      link="iiwa7_link_6" />
    <axis
      xyz="0 0 1" />
    <limit
      lower="-2.09"
      upper="2.09"
      effort="40"
      velocity="3.14" />
  </joint>
  <link
    name="iiwa7_link_7">
    <inertial>
      <origin
        xyz="5.28878934317328E-07 3.37199922245852E-07 -0.0274928177649973"
        rpy="0 0 0" />
      <mass
        value="2.47156969383589" />
      <inertia
        ixx="0.00177365937026673"
        ixy="-1.2410521430667E-07"
        ixz="-2.95409038849194E-08"
        iyy="0.00177328722902027"
        iyz="-1.57567641084958E-08"
        izz="0.00272748710623445" />
    </inertial>
    <visual>
      <origin
        xyz="0 0 0"
        rpy="0 0 0" />
      <geometry>
        <mesh
          filename="./meshes/iiwa7_link_7.STL" />
      </geometry>
      <material
        name="">
        <color
          rgba="0.647058823529412 0.619607843137255 0.588235294117647 1" />
      </material>
    </visual>
    <collision>
      <origin
        xyz="0 0 0"
        rpy="0 0 0" />
      <geometry>
        <mesh
          filename="./meshes/iiwa7_link_7.STL" />
      </geometry>
    </collision>
  </link>
  <joint
    name="iiwa7_joint_7"
    type="revolute">
    <origin
      xyz="0 -0.126 0"
      rpy="1.5708 0 0" />
    <parent
      link="iiwa7_link_6" />
    <child
      link="iiwa7_link_7" />
    <axis
      xyz="0 0 1" />
    <limit
      lower="-3.05"
      upper="3.05"
      effort="40"
      velocity="3.14" />
  </joint>
  <!-- attach Inspirehand to iiwa7_link_7 -->
  <joint name="iiwa7_hand_fixed" type="fixed">
    <!-- <origin xyz="0.5 0.5 0.5" rpy="-1.5707963 0 0" /> -->
    <origin xyz="0.0 0.0 0.0" rpy="-1.5707963 0 0" />
    <parent link="iiwa7_link_7"/>
    <child link="inspirehand_mount"/>
  </joint>
  
  <link name="inspirehand_mount">
    <inertial>
      <origin xyz="0 0 0" rpy="0 0 0" />
      <mass value="0.05" />
      <inertia ixx="1e-4" ixy="0" ixz="0" iyy="1e-4" iyz="0" izz="1e-4" />
    </inertial>
    <visual>
      <origin xyz="0 0 0" rpy="0 0 0" />
      <!-- TODO: add mount mesh if available -->
      <geometry>
        <box size="0.001 0.001 0.001" />
      </geometry>
    </visual>
    <collision>
      <origin xyz="0 0 0" rpy="0 0 0" />
      <geometry>
        <box size="0.001 0.001 0.001" />
      </geometry>
    </collision>
  </link>

  <joint name="inspirehand_mount_joint" type="fixed">
    <origin xyz="0 0 0" rpy="0 0 0" />
    <parent link="inspirehand_mount" />
    <child link="palm" />
  </joint>

  <link
    name="palm">
    <inertial>
      <origin
        xyz="-0.0025264 -0.066047 0.0019598"
        rpy="0 0 0" />
      <mass
        value="0.14143" />
      <inertia
        ixx="0.00012281"
        ixy="2.1711E-06"
        ixz="1.7709E-06"
        iyy="8.3831E-05"
        iyz="-1.655E-06"
        izz="7.6663E-05" />
    </inertial>
    <visual>
      <origin
        xyz="0 0 0"
        rpy="0 0 0" />
      <geometry>
        <mesh
          filename="./meshes/palm.STL" />
      </geometry>
      <material
        name="">
        <color
          rgba="1 1 1 1" />
      </material>
    </visual>
    <collision>
      <origin
        xyz="0 0 0"
        rpy="0 0 0" />
      <geometry>
        <mesh
          filename="./meshes/palm.STL" />
      </geometry>
    </collision>
  </link>

  <!-- index finger -->
  <joint
    name="index_joint_0"
    type="revolute">
    <origin
      xyz="0.00028533 -0.1366 -0.027269"
      rpy="-0.034907 0 3.1416" />
  <parent link="palm" />
  <child link="index_link_0" />
    <axis xyz="0 0 1" />
    <limit
      lower="-2"
      upper="0"
      effort="50"
      velocity="1" />
  </joint>

  <link
    name="index_link_0">
    <inertial>
      <origin
        xyz="0.0031774 0.017383 0.00090008"
        rpy="0 0 0" />
      <mass
        value="0.0042403" />
      <inertia
        ixx="6.6232E-07"
        ixy="1.5775E-08"
        ixz="1.8782E-12"
        iyy="2.1146E-07"
        iyz="5.067E-12"
        izz="6.9398E-07" />
    </inertial>
    <visual>
      <origin
        xyz="0 0 0"
        rpy="0 0 0" />
      <geometry>
        <mesh
          filename="./meshes/index_link_0.STL" />
      </geometry>
      <material
        name="">
        <color
          rgba="1 1 1 1" />
      </material>
    </visual>
    <collision>
      <origin
        xyz="0 0 0"
        rpy="0 0 0" />
      <geometry>
        <mesh
          filename="./meshes/index_link_0.STL" />
      </geometry>
    </collision>
  </link>

  <joint
    name="index_joint_1"
    type="revolute">
    <origin
      xyz="0.0070171 0.037468 -0.00215"
      rpy="0 0 0" />
  <parent
      link="index_link_0" />
  <child
      link="index_link_1" />
    <axis
      xyz="0 0 1" />
    <limit
      lower="-1.7"
      upper="0"
      effort="50"
      velocity="1" />
  </joint>

  <link
    name="index_link_1">
    <inertial>
      <origin
        xyz="-0.0019697 0.019589 0.00305"
        rpy="0 0 0" />
      <mass
        value="0.0045683" />
      <inertia
        ixx="7.6111E-07"
        ixy="-8.7637E-08"
        ixz="-4.2766E-13"
        iyy="9.6076E-08"
        iyz="-1.2085E-12"
        izz="7.8179E-07" />
    </inertial>
    <visual>
      <origin
        xyz="0 0 0"
        rpy="0 0 0" />
      <geometry>
        <mesh
          filename="./meshes/index_link_1.STL" />
      </geometry>
      <material
        name="">
        <color
          rgba="1 1 1 1" />
      </material>
    </visual>
    <collision>
      <origin
        xyz="0 0 0"
        rpy="0 0 0" />
      <geometry>
        <mesh
          filename="./meshes/index_link_1.STL" />
      </geometry>
    </collision>
  </link>

<!-- middle finger -->

  <joint
    name="middle_joint_0"
    type="revolute">
    <origin
      xyz="0.00028533 -0.1371 -0.00795"
      rpy="0 0 3.1416" />
    <parent link="palm" />
    <child link="middle_link_0" />
    <axis xyz="0 0 1" />
    <limit
      lower="-2"
      upper="2"
      effort="50"
      velocity="1" />
  </joint>

  <link
    name="middle_link_0">
    <inertial>
      <origin
        xyz="0.0030737 0.017402 0.00090013"
        rpy="0 0 0" />
      <mass
        value="0.0042403" />
      <inertia
        ixx="6.6211E-07"
        ixy="1.8461E-08"
        ixz="1.798E-12"
        iyy="2.1167E-07"
        iyz="6.6568E-12"
        izz="6.9397E-07" />
    </inertial>
    <visual>
      <origin
        xyz="0 0 0"
        rpy="0 0 0" />
      <geometry>
        <mesh
          filename="./meshes/middle_link_0.STL" />
      </geometry>
      <material
        name="">
        <color
          rgba="1 1 1 1" />
      </material>
    </visual>
    <collision>
      <origin
        xyz="0 0 0"
        rpy="0 0 0" />
      <geometry>
        <mesh
          filename="./meshes/middle_link_0.STL" />
      </geometry>
    </collision>
  </link>

  <joint
    name="middle_joint_1"
    type="revolute">
    <origin
      xyz="0.0067937 0.037509 -0.00215"
      rpy="0 0 0" />
    <parent
      link="middle_link_0" />
    <child
      link="middle_link_1" />
    <axis
      xyz="0 0 -1" />
    <limit
      lower="0"
      upper="1.7"
      effort="50"
      velocity="1" />
  </joint>

  <link
    name="middle_link_1">
    <inertial>
      <origin
        xyz="-0.001921 0.020796 0.00305"
        rpy="0 0 0" />
      <mass
        value="0.0050396" />
      <inertia
        ixx="9.5822E-07"
        ixy="-1.1425E-07"
        ixz="-2.4866E-12"
        iyy="1.0646E-07"
        iyz="-5.9101E-12"
        izz="9.8384E-07" />
    </inertial>
    <visual>
      <origin
        xyz="0 0 0"
        rpy="0 0 0" />
      <geometry>
        <mesh
          filename="./meshes/middle_link_1.STL" />
      </geometry>
      <material
        name="">
        <color
          rgba="1 1 1 1" />
      </material>
    </visual>
    <collision>
      <origin
        xyz="0 0 0"
        rpy="0 0 0" />
      <geometry>
        <mesh
          filename="./meshes/middle_link_1.STL" />
      </geometry>
    </collision>
  </link>
  
 <!-- ring finger -->
  <joint
    name="ring_joint_0"
    type="revolute">
    <origin
      xyz="0.00028533 -0.13681 0.0112844"
      rpy="0.05236 0 -3.1416" />
    <parent link="palm" />
    <child link="ring_link_0" />
    <axis xyz="0 0 1" />
    <limit
      lower="-2"
      upper="0"
      effort="50"
      velocity="1" />
  </joint>

  <link
    name="ring_link_0">
    <inertial>
      <origin
        xyz="0.0030737 0.017402 0.00090015"
        rpy="0 0 0" />
      <mass
        value="0.0042403" />
      <inertia
        ixx="6.6211E-07"
        ixy="1.8461E-08"
        ixz="1.5739E-12"
        iyy="2.1167E-07"
        iyz="6.6326E-12"
        izz="6.9397E-07" />
    </inertial>
    <visual>
      <origin
        xyz="0 0 0"
        rpy="0 0 0" />
      <geometry>
        <mesh
          filename="./meshes/ring_link_0.STL" />
      </geometry>
      <material
        name="">
        <color
          rgba="1 1 1 1" />
      </material>
    </visual>
    <collision>
      <origin
        xyz="0 0 0"
        rpy="0 0 0" />
      <geometry>
        <mesh
          filename="./meshes/ring_link_0.STL" />
      </geometry>
    </collision>
  </link>

  <joint
    name="ring_joint_1"
    type="revolute">
    <origin
      xyz="0.0067937 0.037509 -0.00215"
      rpy="0 0 0" />
    <parent
      link="ring_link_0" />
    <child
      link="ring_link_1" />
    <axis
      xyz="0 0 1" />
    <limit
      lower="-1.7"
      upper="0"
      effort="50"
      velocity="1" />
  </joint>

  <link
    name="ring_link_1">
    <inertial>
      <origin
        xyz="-0.0021753 0.019567 0.00305"
        rpy="0 0 0" />
      <mass
        value="0.0045683" />
      <inertia
        ixx="7.6286E-07"
        ixy="-8.0635E-08"
        ixz="-6.1735E-13"
        iyy="9.431E-08"
        iyz="-5.5495E-13"
        izz="7.8177E-07" />
    </inertial>
    <visual>
      <origin
        xyz="0 0 0"
        rpy="0 0 0" />
      <geometry>
        <mesh
          filename="./meshes/ring_link_1.STL" />
      </geometry>
      <material
        name="">
        <color
          rgba="1 1 1 1" />
      </material>
    </visual>
    <collision>
      <origin
        xyz="0 0 0"
        rpy="0 0 0" />
      <geometry>
        <mesh
          filename="./meshes/ring_link_1.STL" />
      </geometry>
    </collision>
  </link>

<!-- little finger -->
  <joint name="little_joint_0" type="revolute">
  <!-- The joint origin defines the transform from parent link to joint frame -->
  <origin xyz="0.00028533 -0.13551 0.030477" rpy="0.10472 0 -3.1416"/>

  <!-- Parent and child links -->
  <parent link="palm"/>
  <child link="little_link_0"/>

    <!-- Axis of rotation (in joint frame) -->
    <axis xyz="0 0 1"/>

    <!-- Joint limits -->
    <limit lower="-2.0" upper="0.0" effort="100.0" velocity="1.0"/>
  </joint>

  <link
    name="little_link_0">
    <inertial>
      <origin
        xyz="0.0030737 0.017402 0.00090014"
        rpy="0 0 0" />
      <mass
        value="0.0042403" />
      <inertia
        ixx="6.6211E-07"
        ixy="1.8461E-08"
        ixz="1.6126E-12"
        iyy="2.1167E-07"
        iyz="6.6785E-12"
        izz="6.9398E-07" />
    </inertial>
    <visual>
      <origin
        xyz="0 0 0"
        rpy="0 0 0" />
      <geometry>
        <mesh
          filename="./meshes/little_link_0.STL" />
      </geometry>
      <material
        name="">
        <color
          rgba="1 1 1 1" />
      </material>
    </visual>
    <collision>
      <origin
        xyz="0 0 0"
        rpy="0 0 0" />
      <geometry>
        <mesh
          filename="./meshes/little_link_0.STL" />
      </geometry>
    </collision>
  </link>

  <joint
    name="little_joint_1"
    type="revolute">
    <origin
      xyz="0.0067937 0.037509 -0.00215"
      rpy="0 0 0" />
    <parent
      link="little_link_0" />
    <child
      link="little_link_1" />
    <axis
      xyz="0 0 -1" />
    <limit
      lower="0"
      upper="1.7"
      effort="50"
      velocity="1" />
  </joint>

  <link
    name="little_link_1">
    <inertial>
      <origin
        xyz="-0.0024748 0.016203 0.0030531"
        rpy="0 0 0" />
      <mass
        value="0.0035996" />
      <inertia
        ixx="4.3913E-07"
        ixy="-4.1418E-08"
        ixz="3.7169E-11"
        iyy="7.0247E-08"
        iyz="-5.8612E-11"
        izz="4.4867E-07" />
    </inertial>
    <visual>
      <origin
        xyz="0 0 0"
        rpy="0 0 0" />
      <geometry>
        <mesh
          filename="./meshes/little_link_1.STL" />
      </geometry>
      <material
        name="">
        <color
          rgba="1 1 1 1" />
      </material>
    </visual>
    <collision>
      <origin
        xyz="0 0 0"
        rpy="0 0 0" />
      <geometry>
        <mesh
          filename="./meshes/little_link_1.STL" />
      </geometry>
    </collision>
  </link>
 
  <!-- thumb -->
  
  
<joint name="thumb_joint_0" type="revolute">
  <!-- Transform from parent (base_link) to this joint frame -->
  <origin xyz="-0.02296 -0.05885 -0.02045" rpy="1.5708 -1.5708 0"/>

  <!-- Parent and child links -->
  <parent link="palm"/>
  <child link="thumb_link_0"/>

  <!-- Axis of rotation -->
  <axis xyz="0 0 -1"/>

  <!-- Joint limits -->
  <limit lower="-2.0" upper="2.0" effort="50.0" velocity="1.0"/>
</joint>

  <link
    name="thumb_link_0">
    <inertial>
      <origin
        xyz="-0.0078715 0.0065154 0.00388"
        rpy="0 0 0" />
      <mass
        value="0.0018869" />
      <inertia
        ixx="5.816E-08"
        ixy="1.4539E-08"
        ixz="4.491E-09"
        iyy="7.9161E-08"
        iyz="-1.8727E-09"
        izz="6.7433E-08" />
    </inertial>
    <visual>
      <origin
        xyz="0 0 0"
        rpy="0 0 0" />
      <geometry>
        <mesh
          filename="./meshes/thumb_link_0.STL" />
      </geometry>
      <material
        name="">
        <color
          rgba="1 1 1 1" />
      </material>
    </visual>
    <collision>
      <origin
        xyz="0 0 0"
        rpy="0 0 0" />
      <geometry>
        <mesh
          filename="./meshes/thumb_link_0.STL" />
      </geometry>
    </collision>
  </link>

  <joint
    name="thumb_joint_1"
    type="revolute">
    <origin
      xyz="-0.012782 0.013348 0.0022"
      rpy="1.5708 0 2.8587" />
    <parent
      link="thumb_link_0" />
    <child
      link="thumb_link_1" />
    <axis
      xyz="0 0 -1" />
    <limit
      lower="-0.5"
      upper="0"
      effort="50"
      velocity="1" />
  </joint>

  <link
    name="thumb_link_1">
    <inertial>
      <origin
        xyz="0.021932 0.012785 -0.0047886"
        rpy="0 0 0" />
      <mass
        value="0.0066075" />
      <inertia
        ixx="1.5687E-06"
        ixy="-7.8296E-07"
        ixz="8.9144E-10"
        iyy="1.7353E-06"
        iyz="-1.0191E-09"
        izz="2.786E-06" />
    </inertial>
    <visual>
      <origin
        xyz="0 0 0"
        rpy="0 0 0" />
      <geometry>
        <mesh
          filename="./meshes/thumb_link_1.STL" />
      </geometry>
      <material
        name="">
        <color
          rgba="1 1 1 1" />
      </material>
    </visual>
    <collision>
      <origin
        xyz="0 0 0"
        rpy="0 0 0" />
      <geometry>
        <mesh
          filename="./meshes/thumb_link_1.STL" />
      </geometry>
    </collision>
  </link>

<joint name="thumb_joint_2" type="revolute">
  <!-- Transform from parent (Link44) to this joint frame -->
  <origin xyz="0.05507 0.025553 -0.00355" rpy="-3.1416 0 -3.1416"/>

  <!-- Parent and child links -->
  <parent link="thumb_link_1"/>
  <child link="thumb_link_2"/>

  <!-- Axis of rotation (in joint frame) -->
  <axis xyz="0 0 -1"/>

  <!-- Joint limits -->
  <limit lower="-2.0" upper="2.0" effort="50.0" velocity="1.0"/>
</joint>

  <link
    name="thumb_link_2">
    <inertial>
      <origin
        xyz="-0.0060688 0.011295 0.00099972"
        rpy="0 0 0" />
      <mass
        value="0.0037847" />
      <inertia
        ixx="3.6981E-07"
        ixy="9.8581E-08"
        ixz="-4.7472E-12"
        iyy="3.2394E-07"
        iyz="-1.0931E-12"
        izz="4.6531E-07" />
    </inertial>
    <visual>
      <origin
        xyz="0 0 0"
        rpy="0 0 0" />
      <geometry>
        <mesh
          filename="./meshes/thumb_link_2.STL" />
      </geometry>
      <material
        name="">
        <color
          rgba="1 1 1 1" />
      </material>
    </visual>
    <collision>
      <origin
        xyz="0 0 0"
        rpy="0 0 0" />
      <geometry>
        <mesh
          filename="./meshes/thumb_link_2.STL" />
      </geometry>
    </collision>
  </link>

  <joint
    name="thumb_joint_3"
    type="revolute">
    <origin
      xyz="-0.016763 0.023079 -0.00255"
      rpy="0 0 0" />
    <parent
      link="thumb_link_2" />
    <child
      link="thumb_link_3" />
    <axis
      xyz="0 0 -1" />
    <limit
      lower="0"
      upper="1.2"
      effort="50"
      velocity="1" />
  </joint>

  <link
    name="thumb_link_3">
    <inertial>
      <origin
        xyz="-0.0092888 0.0049529 0.0035533"
        rpy="0 0 0" />
      <mass
        value="0.0033441" />
      <inertia
        ixx="1.3632E-07"
        ixy="5.6788E-08"
        ixz="-9.2801E-11"
        iyy="1.4052E-07"
        iyz="1.2283E-10"
        izz="2.0026E-07" />
    </inertial>
    <visual>
      <origin
        xyz="0 0 0"
        rpy="0 0 0" />
      <geometry>
        <mesh
          filename="./meshes/thumb_link_3.STL" />
      </geometry>
      <material
        name="">
        <color
          rgba="1 1 1 1" />
      </material>
    </visual>
    <collision>
      <origin
        xyz="0 0 0"
        rpy="0 0 0" />
      <geometry>
        <mesh
          filename="./meshes/thumb_link_3.STL" />
      </geometry>
    </collision>
  </link>
</robot>
